(venv) PS C:\Users\HP\ecommerce_project> python manage.py makemigrations 
No changes detected
(venv) PS C:\Users\HP\ecommerce_project> python manage.py migrate        
Operations to perform:
  Apply all migrations: admin, auth, catalog, contenttypes, sessions
Running migrations:
  No migrations to apply.
(venv) PS C:\Users\HP\ecommerce_project> python manage.py runserver     
Watching for file changes with StatReloader
Performing system checks...

System check identified no issues (0 silenced).
September 14, 2025 - 01:47:07
Django version 5.2.6, using settings 'ecommerce.settings'
Starting development server at http://127.0.0.1:8000/
Quit the server with CTRL-BREAK.

WARNING: This is a development server. Do not use it in a production setting. Use a production WSGI or ASGI server instead.
For more information on production servers see: https://docs.djangoproject.com/en/5.2/howto/deployment/
[14/Sep/2025 01:47:32] "GET /api/docs/ HTTP/1.1" 200 2226
[14/Sep/2025 01:47:32] "GET /api/docs/?format=openapi HTTP/1.1" 200 7891
Method Not Allowed: /api/token/
[14/Sep/2025 01:47:39] "GET /api/token/ HTTP/1.1" 405 12478
C:\Users\HP\ecommerce_project\venv\Lib\site-packages\django\views\debug.py:505: ExceptionCycleWarning: Cycle in the exception chain detected: exception 'Error 10061 connecting to 127.0.0.1:6379. No connection could be made because the target machine actively refused it.' encountered again.
  warnings.warn(
Internal Server Error: /api/products/
Traceback (most recent call last):
  File "C:\Users\HP\ecommerce_project\venv\Lib\site-packages\django_redis\cache.py", line 29, in _decorator       
    return method(self, *args, **kwargs)
           ^^^^^^^^^^^^^^^^^^^^^^^^^^^^^
  File "C:\Users\HP\ecommerce_project\venv\Lib\site-packages\django_redis\cache.py", line 99, in _get
    return self.client.get(key, default=default, version=version, client=client)
           ^^^^^^^^^^^^^^^^^^^^^^^^^^^^^^^^^^^^^^^^^^^^^^^^^^^^^^^^^^^^^^^^^^^^^
  File "C:\Users\HP\ecommerce_project\venv\Lib\site-packages\django_redis\client\default.py", line 300, in get    
    raise ConnectionInterrupted(connection=client) from e
django_redis.exceptions.ConnectionInterrupted: Redis ConnectionError: Error 10061 connecting to 127.0.0.1:6379. No connection could be made because the target machine actively refused it.

During handling of the above exception, another exception occurred:

Traceback (most recent call last):
  File "C:\Users\HP\ecommerce_project\venv\Lib\site-packages\django\core\handlers\exception.py", line 55, in inner
    response = get_response(request)
               ^^^^^^^^^^^^^^^^^^^^^
  File "C:\Users\HP\ecommerce_project\venv\Lib\site-packages\django\core\handlers\base.py", line 197, in _get_response
    response = wrapped_callback(request, *callback_args, **callback_kwargs)
               ^^^^^^^^^^^^^^^^^^^^^^^^^^^^^^^^^^^^^^^^^^^^^^^^^^^^^^^^^^^^
  File "C:\Users\HP\ecommerce_project\venv\Lib\site-packages\django\views\decorators\csrf.py", line 65, in _view_wrapper
    return view_func(request, *args, **kwargs)
           ^^^^^^^^^^^^^^^^^^^^^^^^^^^^^^^^^^^
  File "C:\Users\HP\ecommerce_project\venv\Lib\site-packages\rest_framework\viewsets.py", line 125, in view       
    return self.dispatch(request, *args, **kwargs)
           ^^^^^^^^^^^^^^^^^^^^^^^^^^^^^^^^^^^^^^^
  File "C:\Users\HP\ecommerce_project\venv\Lib\site-packages\rest_framework\views.py", line 515, in dispatch      
    response = self.handle_exception(exc)
               ^^^^^^^^^^^^^^^^^^^^^^^^^^
  File "C:\Users\HP\ecommerce_project\venv\Lib\site-packages\rest_framework\views.py", line 475, in handle_exception
    self.raise_uncaught_exception(exc)
  File "C:\Users\HP\ecommerce_project\venv\Lib\site-packages\rest_framework\views.py", line 486, in raise_uncaught_exception
    raise exc
  File "C:\Users\HP\ecommerce_project\venv\Lib\site-packages\rest_framework\views.py", line 512, in dispatch      
    response = handler(request, *args, **kwargs)
               ^^^^^^^^^^^^^^^^^^^^^^^^^^^^^^^^^
  File "C:\Users\HP\ecommerce_project\venv\Lib\site-packages\django\utils\decorators.py", line 48, in _wrapper    
    return bound_method(*args, **kwargs)
           ^^^^^^^^^^^^^^^^^^^^^^^^^^^^^
  File "C:\Users\HP\ecommerce_project\venv\Lib\site-packages\django\utils\decorators.py", line 185, in _view_wrapper
    result = _pre_process_request(request, *args, **kwargs)
             ^^^^^^^^^^^^^^^^^^^^^^^^^^^^^^^^^^^^^^^^^^^^^^
  File "C:\Users\HP\ecommerce_project\venv\Lib\site-packages\django\utils\decorators.py", line 131, in _pre_process_request
    result = middleware.process_request(request)
             ^^^^^^^^^^^^^^^^^^^^^^^^^^^^^^^^^^^
  File "C:\Users\HP\ecommerce_project\venv\Lib\site-packages\django\middleware\cache.py", line 161, in process_request
    cache_key = get_cache_key(request, self.key_prefix, "GET", cache=self.cache)
                ^^^^^^^^^^^^^^^^^^^^^^^^^^^^^^^^^^^^^^^^^^^^^^^^^^^^^^^^^^^^^^^^
  File "C:\Users\HP\ecommerce_project\venv\Lib\site-packages\django\utils\cache.py", line 392, in get_cache_key   
    headerlist = cache.get(cache_key)
                 ^^^^^^^^^^^^^^^^^^^^
  File "C:\Users\HP\ecommerce_project\venv\Lib\site-packages\django_redis\cache.py", line 92, in get
    value = self._get(key, default, version, client)
            ^^^^^^^^^^^^^^^^^^^^^^^^^^^^^^^^^^^^^^^^
  File "C:\Users\HP\ecommerce_project\venv\Lib\site-packages\django_redis\cache.py", line 36, in _decorator       
    raise e.__cause__  # noqa: B904
    ^^^^^^^^^^^^^^^^^
  File "C:\Users\HP\ecommerce_project\venv\Lib\site-packages\django_redis\client\default.py", line 298, in get    
    value = client.get(key)
            ^^^^^^^^^^^^^^^
  File "C:\Users\HP\ecommerce_project\venv\Lib\site-packages\redis\commands\core.py", line 1829, in get
    return self.execute_command("GET", name, keys=[name])
           ^^^^^^^^^^^^^^^^^^^^^^^^^^^^^^^^^^^^^^^^^^^^^^
  File "C:\Users\HP\ecommerce_project\venv\Lib\site-packages\redis\client.py", line 621, in execute_command       
    return self._execute_command(*args, **options)
           ^^^^^^^^^^^^^^^^^^^^^^^^^^^^^^^^^^^^^^^
  File "C:\Users\HP\ecommerce_project\venv\Lib\site-packages\redis\client.py", line 627, in _execute_command      
    conn = self.connection or pool.get_connection()
                              ^^^^^^^^^^^^^^^^^^^^^
  File "C:\Users\HP\ecommerce_project\venv\Lib\site-packages\redis\utils.py", line 195, in wrapper
    return func(*args, **kwargs)
           ^^^^^^^^^^^^^^^^^^^^^
  File "C:\Users\HP\ecommerce_project\venv\Lib\site-packages\redis\connection.py", line 1533, in get_connection   
    connection.connect()
  File "C:\Users\HP\ecommerce_project\venv\Lib\site-packages\redis\connection.py", line 380, in connect
    self.connect_check_health(check_health=True)
  File "C:\Users\HP\ecommerce_project\venv\Lib\site-packages\redis\connection.py", line 397, in connect_check_health
    raise ConnectionError(self._error_message(e))
redis.exceptions.ConnectionError: Error 10061 connecting to 127.0.0.1:6379. No connection could be made because the target machine actively refused it.
[14/Sep/2025 01:48:01] "GET /api/products/?category=1&ordering=price HTTP/1.1" 500 182207
